Workbook

Sheet START HERE
A1: COFFEE BUSINESS EXCEL TRACKER
A3: Use the sheets in order: Menu & Pricing → Orders → Expenses → Inventory → Cash Flow → Dashboard.
A5: Step | B5: Action | C5: Sheet
A6: 1 | B6: Set your business name and tracker start date. | C6: Lists
A7: 2 | B7: Replace sample products and update prices and estimated costs. | C7: Menu & Pricing
A8: 3 | B8: Enter one row for every item sold. Repeat the same Order ID for multiple items. | C8: Orders
A9: 4 | B9: Record all business expenses and choose the correct expense type. | C9: Expenses
A10: 5 | B10: Update stock in, stock used, and wastage. | C10: Inventory
A11: 6 | B11: Enter actual closing cash for daily reconciliation. | C11: Cash Flow
A12: 7 | B12: Choose report dates and review sales, expenses, and profit. | C12: Dashboard
A14: Term | B14: Meaning
A15: Gross Sales | B15: Price × quantity plus add-ons, before discounts.
A16: Net Sales | B16: Gross Sales less discounts; only paid and completed orders count.
A17: Estimated COGS | B17: Estimated cost of the products sold.
A18: Operating Expenses | B18: Day-to-day business costs used to calculate profit.
A19: Gross Profit | B19: Net Sales − Estimated COGS.
A20: Net Profit | B20: Gross Profit − Operating Expenses.
A21: Paid Cash Out | B21: All paid expenses, including inventory and capital purchases.

Sheet Dashboard
A1: COFFEE BUSINESS DASHBOARD
A3: Report Start Date | B3: 46216 | D3: Report End Date | E3: 46216 | P3: Menu Item / Variant | Q3: Qty Sold | R3: Net Sales (₱) | S3: Est. COGS (₱) | T3: Gross Profit (₱)
A4: Business Name | B4: =Lists!B4 -> My Coffee Business | P4: ='Menu & Pricing'!A5 -> Americano - Regular | Q4: =IF(P4="","",SUMIFS(Orders!$H$5:$H$154,Orders!$F$5:$F$154,P4,Orders!$B$5:$B$154,">="&$B$3,Orders!$B$5:$B$154,"<="&$E$3,Orders!$Q$5:$Q$154,"Paid",Orders!$R$5:$R$154,"Completed")) -> 0 | R4: =IF(P4="","",SUMIFS(Orders!$M$5:$M$154,Orders!$F$5:$F$154,P4,Orders!$B$5:$B$154,">="&$B$3,Orders!$B$5:$B$154,"<="&$E$3,Orders!$Q$5:$Q$154,"Paid",Orders!$R$5:$R$154,"Completed")) -> 0 | S4: =IF(P4="","",SUMIFS(Orders!$O$5:$O$154,Orders!$F$5:$F$154,P4,Orders!$B$5:$B$154,">="&$B$3,Orders!$B$5:$B$154,"<="&$E$3,Orders!$Q$5:$Q$154,"Paid",Orders!$R$5:$R$154,"Completed")) -> 0 | T4: =IF(P4="","",R4-S4) -> 0
P5: ='Menu & Pricing'!A6 -> Cafe Latte - Regular | Q5: =IF(P5="","",SUMIFS(Orders!$H$5:$H$154,Orders!$F$5:$F$154,P5,Orders!$B$5:$B$154,">="&$B$3,Orders!$B$5:$B$154,"<="&$E$3,Orders!$Q$5:$Q$154,"Paid",Orders!$R$5:$R$154,"Completed")) -> 0 | R5: =IF(P5="","",SUMIFS(Orders!$M$5:$M$154,Orders!$F$5:$F$154,P5,Orders!$B$5:$B$154,">="&$B$3,Orders!$B$5:$B$154,"<="&$E$3,Orders!$Q$5:$Q$154,"Paid",Orders!$R$5:$R$154,"Completed")) -> 0 | S5: =IF(P5="","",SUMIFS(Orders!$O$5:$O$154,Orders!$F$5:$F$154,P5,Orders!$B$5:$B$154,">="&$B$3,Orders!$B$5:$B$154,"<="&$E$3,Orders!$Q$5:$Q$154,"Paid",Orders!$R$5:$R$154,"Completed")) -> 0 | T5: =IF(P5="","",R5-S5) -> 0
A6: Gross Sales | D6: Net Sales | G6: Estimated COGS | J6: Operating Expenses | P6: ='Menu & Pricing'!A7 -> Spanish Latte - Regular | Q6: =IF(P6="","",SUMIFS(Orders!$H$5:$H$154,Orders!$F$5:$F$154,P6,Orders!$B$5:$B$154,">="&$B$3,Orders!$B$5:$B$154,"<="&$E$3,Orders!$Q$5:$Q$154,"Paid",Orders!$R$5:$R$154,"Completed")) -> 0 | R6: =IF(P6="","",SUMIFS(Orders!$M$5:$M$154,Orders!$F$5:$F$154,P6,Orders!$B$5:$B$154,">="&$B$3,Orders!$B$5:$B$154,"<="&$E$3,Orders!$Q$5:$Q$154,"Paid",Orders!$R$5:$R$154,"Completed")) -> 0 | S6: =IF(P6="","",SUMIFS(Orders!$O$5:$O$154,Orders!$F$5:$F$154,P6,Orders!$B$5:$B$154,">="&$B$3,Orders!$B$5:$B$154,"<="&$E$3,Orders!$Q$5:$Q$154,"Paid",Orders!$R$5:$R$154,"Completed")) -> 0 | T6: =IF(P6="","",R6-S6) -> 0
A7: =SUMIFS(Orders!$K$5:$K$154,Orders!$B$5:$B$154,">="&$B$3,Orders!$B$5:$B$154,"<="&$E$3,Orders!$Q$5:$Q$154,"Paid",Orders!$R$5:$R$154,"Completed") -> 0 | D7: =SUMIFS(Orders!$M$5:$M$154,Orders!$B$5:$B$154,">="&$B$3,Orders!$B$5:$B$154,"<="&$E$3,Orders!$Q$5:$Q$154,"Paid",Orders!$R$5:$R$154,"Completed") -> 0 | G7: =SUMIFS(Orders!$O$5:$O$154,Orders!$B$5:$B$154,">="&$B$3,Orders!$B$5:$B$154,"<="&$E$3,Orders!$Q$5:$Q$154,"Paid",Orders!$R$5:$R$154,"Completed") -> 0 | J7: =SUMIFS(Expenses!$J$5:$J$104,Expenses!$B$5:$B$104,">="&$B$3,Expenses!$B$5:$B$104,"<="&$E$3,Expenses!$L$5:$L$104,"Operating Expense",Expenses!$M$5:$M$104,"Paid") -> 0 | P7: ='Menu & Pricing'!A8 -> Caramel Macchiato - Regular | Q7: =IF(P7="","",SUMIFS(Orders!$H$5:$H$154,Orders!$F$5:$F$154,P7,Orders!$B$5:$B$154,">="&$B$3,Orders!$B$5:$B$154,"<="&$E$3,Orders!$Q$5:$Q$154,"Paid",Orders!$R$5:$R$154,"Completed")) -> 0 | R7: =IF(P7="","",SUMIFS(Orders!$M$5:$M$154,Orders!$F$5:$F$154,P7,Orders!$B$5:$B$154,">="&$B$3,Orders!$B$5:$B$154,"<="&$E$3,Orders!$Q$5:$Q$154,"Paid",Orders!$R$5:$R$154,"Completed")) -> 0 | S7: =IF(P7="","",SUMIFS(Orders!$O$5:$O$154,Orders!$F$5:$F$154,P7,Orders!$B$5:$B$154,">="&$B$3,Orders!$B$5:$B$154,"<="&$E$3,Orders!$Q$5:$Q$154,"Paid",Orders!$R$5:$R$154,"Completed")) -> 0 | T7: =IF(P7="","",R7-S7) -> 0
P8: ='Menu & Pricing'!A9 -> Matcha Latte - Regular | Q8: =IF(P8="","",SUMIFS(Orders!$H$5:$H$154,Orders!$F$5:$F$154,P8,Orders!$B$5:$B$154,">="&$B$3,Orders!$B$5:$B$154,"<="&$E$3,Orders!$Q$5:$Q$154,"Paid",Orders!$R$5:$R$154,"Completed")) -> 0 | R8: =IF(P8="","",SUMIFS(Orders!$M$5:$M$154,Orders!$F$5:$F$154,P8,Orders!$B$5:$B$154,">="&$B$3,Orders!$B$5:$B$154,"<="&$E$3,Orders!$Q$5:$Q$154,"Paid",Orders!$R$5:$R$154,"Completed")) -> 0 | S8: =IF(P8="","",SUMIFS(Orders!$O$5:$O$154,Orders!$F$5:$F$154,P8,Orders!$B$5:$B$154,">="&$B$3,Orders!$B$5:$B$154,"<="&$E$3,Orders!$Q$5:$Q$154,"Paid",Orders!$R$5:$R$154,"Completed")) -> 0 | T8: =IF(P8="","",R8-S8) -> 0
P9: ='Menu & Pricing'!A10 -> Chocolate Drink - Regular | Q9: =IF(P9="","",SUMIFS(Orders!$H$5:$H$154,Orders!$F$5:$F$154,P9,Orders!$B$5:$B$154,">="&$B$3,Orders!$B$5:$B$154,"<="&$E$3,Orders!$Q$5:$Q$154,"Paid",Orders!$R$5:$R$154,"Completed")) -> 0 | R9: =IF(P9="","",SUMIFS(Orders!$M$5:$M$154,Orders!$F$5:$F$154,P9,Orders!$B$5:$B$154,">="&$B$3,Orders!$B$5:$B$154,"<="&$E$3,Orders!$Q$5:$Q$154,"Paid",Orders!$R$5:$R$154,"Completed")) -> 0 | S9: =IF(P9="","",SUMIFS(Orders!$O$5:$O$154,Orders!$F$5:$F$154,P9,Orders!$B$5:$B$154,">="&$B$3,Orders!$B$5:$B$154,"<="&$E$3,Orders!$Q$5:$Q$154,"Paid",Orders!$R$5:$R$154,"Completed")) -> 0 | T9: =IF(P9="","",R9-S9) -> 0
P10: ='Menu & Pricing'!A11 -> Croissant | Q10: =IF(P10="","",SUMIFS(Orders!$H$5:$H$154,Orders!$F$5:$F$154,P10,Orders!$B$5:$B$154,">="&$B$3,Orders!$B$5:$B$154,"<="&$E$3,Orders!$Q$5:$Q$154,"Paid",Orders!$R$5:$R$154,"Completed")) -> 0 | R10: =IF(P10="","",SUMIFS(Orders!$M$5:$M$154,Orders!$F$5:$F$154,P10,Orders!$B$5:$B$154,">="&$B$3,Orders!$B$5:$B$154,"<="&$E$3,Orders!$Q$5:$Q$154,"Paid",Orders!$R$5:$R$154,"Completed")) -> 0 | S10: =IF(P10="","",SUMIFS(Orders!$O$5:$O$154,Orders!$F$5:$F$154,P10,Orders!$B$5:$B$154,">="&$B$3,Orders!$B$5:$B$154,"<="&$E$3,Orders!$Q$5:$Q$154,"Paid",Orders!$R$5:$R$154,"Completed")) -> 0 | T10: =IF(P10="","",R10-S10) -> 0
A11: Gross Profit | D11: Net Profit | G11: Total Orders | J11: Items Sold | P11: ='Menu & Pricing'!A12 -> Extra Espresso Shot | Q11: =IF(P11="","",SUMIFS(Orders!$H$5:$H$154,Orders!$F$5:$F$154,P11,Orders!$B$5:$B$154,">="&$B$3,Orders!$B$5:$B$154,"<="&$E$3,Orders!$Q$5:$Q$154,"Paid",Orders!$R$5:$R$154,"Completed")) -> 0 | R11: =IF(P11="","",SUMIFS(Orders!$M$5:$M$154,Orders!$F$5:$F$154,P11,Orders!$B$5:$B$154,">="&$B$3,Orders!$B$5:$B$154,"<="&$E$3,Orders!$Q$5:$Q$154,"Paid",Orders!$R$5:$R$154,"Completed")) -> 0 | S11: =IF(P11="","",SUMIFS(Orders!$O$5:$O$154,Orders!$F$5:$F$154,P11,Orders!$B$5:$B$154,">="&$B$3,Orders!$B$5:$B$154,"<="&$E$3,Orders!$Q$5:$Q$154,"Paid",Orders!$R$5:$R$154,"Completed")) -> 0 | T11: =IF(P11="","",R11-S11) -> 0
A12: =D7-G7 -> 0 | D12: =A12-J7 -> 0 | G12: =SUMIFS(Orders!$U$5:$U$154,Orders!$B$5:$B$154,">="&$B$3,Orders!$B$5:$B$154,"<="&$E$3) -> 0 | J12: =SUMIFS(Orders!$H$5:$H$154,Orders!$B$5:$B$154,">="&$B$3,Orders!$B$5:$B$154,"<="&$E$3,Orders!$Q$5:$Q$154,"Paid",Orders!$R$5:$R$154,"Completed") -> 0 | P12: ='Menu & Pricing'!A13 -> 0 | Q12: =IF(P12="","",SUMIFS(Orders!$H$5:$H$154,Orders!$F$5:$F$154,P12,Orders!$B$5:$B$154,">="&$B$3,Orders!$B$5:$B$154,"<="&$E$3,Orders!$Q$5:$Q$154,"Paid",Orders!$R$5:$R$154,"Completed")) -> 0 | R12: =IF(P12="","",SUMIFS(Orders!$M$5:$M$154,Orders!$F$5:$F$154,P12,Orders!$B$5:$B$154,">="&$B$3,Orders!$B$5:$B$154,"<="&$E$3,Orders!$Q$5:$Q$154,"Paid",Orders!$R$5:$R$154,"Completed")) -> 0 | S12: =IF(P12="","",SUMIFS(Orders!$O$5:$O$154,Orders!$F$5:$F$154,P12,Orders!$B$5:$B$154,">="&$B$3,Orders!$B$5:$B$154,"<="&$E$3,Orders!$Q$5:$Q$154,"Paid",Orders!$R$5:$R$154,"Completed")) -> 0 | T12: =IF(P12="","",R12-S12) -> 0
P13: ='Menu & Pricing'!A14 -> 0 | Q13: =IF(P13="","",SUMIFS(Orders!$H$5:$H$154,Orders!$F$5:$F$154,P13,Orders!$B$5:$B$154,">="&$B$3,Orders!$B$5:$B$154,"<="&$E$3,Orders!$Q$5:$Q$154,"Paid",Orders!$R$5:$R$154,"Completed")) -> 0 | R13: =IF(P13="","",SUMIFS(Orders!$M$5:$M$154,Orders!$F$5:$F$154,P13,Orders!$B$5:$B$154,">="&$B$3,Orders!$B$5:$B$154,"<="&$E$3,Orders!$Q$5:$Q$154,"Paid",Orders!$R$5:$R$154,"Completed")) -> 0 | S13: =IF(P13="","",SUMIFS(Orders!$O$5:$O$154,Orders!$F$5:$F$154,P13,Orders!$B$5:$B$154,">="&$B$3,Orders!$B$5:$B$154,"<="&$E$3,Orders!$Q$5:$Q$154,"Paid",Orders!$R$5:$R$154,"Completed")) -> 0 | T13: =IF(P13="","",R13-S13) -> 0
P14: ='Menu & Pricing'!A15 -> 0 | Q14: =IF(P14="","",SUMIFS(Orders!$H$5:$H$154,Orders!$F$5:$F$154,P14,Orders!$B$5:$B$154,">="&$B$3,Orders!$B$5:$B$154,"<="&$E$3,Orders!$Q$5:$Q$154,"Paid",Orders!$R$5:$R$154,"Completed")) -> 0 | R14: =IF(P14="","",SUMIFS(Orders!$M$5:$M$154,Orders!$F$5:$F$154,P14,Orders!$B$5:$B$154,">="&$B$3,Orders!$B$5:$B$154,"<="&$E$3,Orders!$Q$5:$Q$154,"Paid",Orders!$R$5:$R$154,"Completed")) -> 0 | S14: =IF(P14="","",SUMIFS(Orders!$O$5:$O$154,Orders!$F$5:$F$154,P14,Orders!$B$5:$B$154,">="&$B$3,Orders!$B$5:$B$154,"<="&$E$3,Orders!$Q$5:$Q$154,"Paid",Orders!$R$5:$R$154,"Completed")) -> 0 | T14: =IF(P14="","",R14-S14) -> 0
P15: ='Menu & Pricing'!A16 -> 0 | Q15: =IF(P15="","",SUMIFS(Orders!$H$5:$H$154,Orders!$F$5:$F$154,P15,Orders!$B$5:$B$154,">="&$B$3,Orders!$B$5:$B$154,"<="&$E$3,Orders!$Q$5:$Q$154,"Paid",Orders!$R$5:$R$154,"Completed")) -> 0 | R15: =IF(P15="","",SUMIFS(Orders!$M$5:$M$154,Orders!$F$5:$F$154,P15,Orders!$B$5:$B$154,">="&$B$3,Orders!$B$5:$B$154,"<="&$E$3,Orders!$Q$5:$Q$154,"Paid",Orders!$R$5:$R$154,"Completed")) -> 0 | S15: =IF(P15="","",SUMIFS(Orders!$O$5:$O$154,Orders!$F$5:$F$154,P15,Orders!$B$5:$B$154,">="&$B$3,Orders!$B$5:$B$154,"<="&$E$3,Orders!$Q$5:$Q$154,"Paid",Orders!$R$5:$R$154,"Completed")) -> 0 | T15: =IF(P15="","",R15-S15) -> 0
A16: BUSINESS INSIGHTS | P16: ='Menu & Pricing'!A17 -> 0 | Q16: =IF(P16="","",SUMIFS(Orders!$H$5:$H$154,Orders!$F$5:$F$154,P16,Orders!$B$5:$B$154,">="&$B$3,Orders!$B$5:$B$154,"<="&$E$3,Orders!$Q$5:$Q$154,"Paid",Orders!$R$5:$R$154,"Completed")) -> 0 | R16: =IF(P16="","",SUMIFS(Orders!$M$5:$M$154,Orders!$F$5:$F$154,P16,Orders!$B$5:$B$154,">="&$B$3,Orders!$B$5:$B$154,"<="&$E$3,Orders!$Q$5:$Q$154,"Paid",Orders!$R$5:$R$154,"Completed")) -> 0 | S16: =IF(P16="","",SUMIFS(Orders!$O$5:$O$154,Orders!$F$5:$F$154,P16,Orders!$B$5:$B$154,">="&$B$3,Orders!$B$5:$B$154,"<="&$E$3,Orders!$Q$5:$Q$154,"Paid",Orders!$R$5:$R$154,"Completed")) -> 0 | T16: =IF(P16="","",R16-S16) -> 0
P17: ='Menu & Pricing'!A18 -> 0 | Q17: =IF(P17="","",SUMIFS(Orders!$H$5:$H$154,Orders!$F$5:$F$154,P17,Orders!$B$5:$B$154,">="&$B$3,Orders!$B$5:$B$154,"<="&$E$3,Orders!$Q$5:$Q$154,"Paid",Orders!$R$5:$R$154,"Completed")) -> 0 | R17: =IF(P17="","",SUMIFS(Orders!$M$5:$M$154,Orders!$F$5:$F$154,P17,Orders!$B$5:$B$154,">="&$B$3,Orders!$B$5:$B$154,"<="&$E$3,Orders!$Q$5:$Q$154,"Paid",Orders!$R$5:$R$154,"Completed")) -> 0 | S17: =IF(P17="","",SUMIFS(Orders!$O$5:$O$154,Orders!$F$5:$F$154,P17,Orders!$B$5:$B$154,">="&$B$3,Orders!$B$5:$B$154,"<="&$E$3,Orders!$Q$5:$Q$154,"Paid",Orders!$R$5:$R$154,"Completed")) -> 0 | T17: =IF(P17="","",R17-S17) -> 0
A18: Metric | B18: Result | D18: Metric | E18: Result | P18: ='Menu & Pricing'!A19 -> 0 | Q18: =IF(P18="","",SUMIFS(Orders!$H$5:$H$154,Orders!$F$5:$F$154,P18,Orders!$B$5:$B$154,">="&$B$3,Orders!$B$5:$B$154,"<="&$E$3,Orders!$Q$5:$Q$154,"Paid",Orders!$R$5:$R$154,"Completed")) -> 0 | R18: =IF(P18="","",SUMIFS(Orders!$M$5:$M$154,Orders!$F$5:$F$154,P18,Orders!$B$5:$B$154,">="&$B$3,Orders!$B$5:$B$154,"<="&$E$3,Orders!$Q$5:$Q$154,"Paid",Orders!$R$5:$R$154,"Completed")) -> 0 | S18: =IF(P18="","",SUMIFS(Orders!$O$5:$O$154,Orders!$F$5:$F$154,P18,Orders!$B$5:$B$154,">="&$B$3,Orders!$B$5:$B$154,"<="&$E$3,Orders!$Q$5:$Q$154,"Paid",Orders!$R$5:$R$154,"Completed")) -> 0 | T18: =IF(P18="","",R18-S18) -> 0
A19: Best-Selling Product | B19: =IF(MAX($Q$4:$Q$53)=0,"No completed sales",INDEX($P$4:$P$53,MATCH(MAX($Q$4:$Q$53),$Q$4:$Q$53,0))) -> No completed sales | D19: Gross Margin | E19: =IFERROR(A12/D7,0) -> 0 | P19: ='Menu & Pricing'!A20 -> 0 | Q19: =IF(P19="","",SUMIFS(Orders!$H$5:$H$154,Orders!$F$5:$F$154,P19,Orders!$B$5:$B$154,">="&$B$3,Orders!$B$5:$B$154,"<="&$E$3,Orders!$Q$5:$Q$154,"Paid",Orders!$R$5:$R$154,"Completed")) -> 0 | R19: =IF(P19="","",SUMIFS(Orders!$M$5:$M$154,Orders!$F$5:$F$154,P19,Orders!$B$5:$B$154,">="&$B$3,Orders!$B$5:$B$154,"<="&$E$3,Orders!$Q$5:$Q$154,"Paid",Orders!$R$5:$R$154,"Completed")) -> 0 | S19: =IF(P19="","",SUMIFS(Orders!$O$5:$O$154,Orders!$F$5:$F$154,P19,Orders!$B$5:$B$154,">="&$B$3,Orders!$B$5:$B$154,"<="&$E$3,Orders!$Q$5:$Q$154,"Paid",Orders!$R$5:$R$154,"Completed")) -> 0 | T19: =IF(P19="","",R19-S19) -> 0
A20: Average Order Value | B20: =IFERROR(D7/G12,0) -> 0 | D20: Paid Cash Out | E20: =SUMIFS(Expenses!$J$5:$J$104,Expenses!$B$5:$B$104,">="&$B$3,Expenses!$B$5:$B$104,"<="&$E$3,Expenses!$M$5:$M$104,"Paid") -> 0 | P20: ='Menu & Pricing'!A21 -> 0 | Q20: =IF(P20="","",SUMIFS(Orders!$H$5:$H$154,Orders!$F$5:$F$154,P20,Orders!$B$5:$B$154,">="&$B$3,Orders!$B$5:$B$154,"<="&$E$3,Orders!$Q$5:$Q$154,"Paid",Orders!$R$5:$R$154,"Completed")) -> 0 | R20: =IF(P20="","",SUMIFS(Orders!$M$5:$M$154,Orders!$F$5:$F$154,P20,Orders!$B$5:$B$154,">="&$B$3,Orders!$B$5:$B$154,"<="&$E$3,Orders!$Q$5:$Q$154,"Paid",Orders!$R$5:$R$154,"Completed")) -> 0 | S20: =IF(P20="","",SUMIFS(Orders!$O$5:$O$154,Orders!$F$5:$F$154,P20,Orders!$B$5:$B$154,">="&$B$3,Orders!$B$5:$B$154,"<="&$E$3,Orders!$Q$5:$Q$154,"Paid",Orders!$R$5:$R$154,"Completed")) -> 0 | T20: =IF(P20="","",R20-S20) -> 0
A21: Cash Sales | B21: =SUMIFS(Orders!$M$5:$M$154,Orders!$B$5:$B$154,">="&$B$3,Orders!$B$5:$B$154,"<="&$E$3,Orders!$P$5:$P$154,"Cash",Orders!$Q$5:$Q$154,"Paid",Orders!$R$5:$R$154,"Completed") -> 0 | D21: Report Days | E21: =MAX(0,E3-B3+1) -> 1 | P21: ='Menu & Pricing'!A22 -> 0 | Q21: =IF(P21="","",SUMIFS(Orders!$H$5:$H$154,Orders!$F$5:$F$154,P21,Orders!$B$5:$B$154,">="&$B$3,Orders!$B$5:$B$154,"<="&$E$3,Orders!$Q$5:$Q$154,"Paid",Orders!$R$5:$R$154,"Completed")) -> 0 | R21: =IF(P21="","",SUMIFS(Orders!$M$5:$M$154,Orders!$F$5:$F$154,P21,Orders!$B$5:$B$154,">="&$B$3,Orders!$B$5:$B$154,"<="&$E$3,Orders!$Q$5:$Q$154,"Paid",Orders!$R$5:$R$154,"Completed")) -> 0 | S21: =IF(P21="","",SUMIFS(Orders!$O$5:$O$154,Orders!$F$5:$F$154,P21,Orders!$B$5:$B$154,">="&$B$3,Orders!$B$5:$B$154,"<="&$E$3,Orders!$Q$5:$Q$154,"Paid",Orders!$R$5:$R$154,"Completed")) -> 0 | T21: =IF(P21="","",R21-S21) -> 0
A22: Digital Sales | B22: =D7-B21 -> 0 | D22: Net Cash Movement | E22: =B21-E20 -> 0 | P22: ='Menu & Pricing'!A23 -> 0 | Q22: =IF(P22="","",SUMIFS(Orders!$H$5:$H$154,Orders!$F$5:$F$154,P22,Orders!$B$5:$B$154,">="&$B$3,Orders!$B$5:$B$154,"<="&$E$3,Orders!$Q$5:$Q$154,"Paid",Orders!$R$5:$R$154,"Completed")) -> 0 | R22: =IF(P22="","",SUMIFS(Orders!$M$5:$M$154,Orders!$F$5:$F$154,P22,Orders!$B$5:$B$154,">="&$B$3,Orders!$B$5:$B$154,"<="&$E$3,Orders!$Q$5:$Q$154,"Paid",Orders!$R$5:$R$154,"Completed")) -> 0 | S22: =IF(P22="","",SUMIFS(Orders!$O$5:$O$154,Orders!$F$5:$F$154,P22,Orders!$B$5:$B$154,">="&$B$3,Orders!$B$5:$B$154,"<="&$E$3,Orders!$Q$5:$Q$154,"Paid",Orders!$R$5:$R$154,"Completed")) -> 0 | T22: =IF(P22="","",R22-S22) -> 0
P23: ='Menu & Pricing'!A24 -> 0 | Q23: =IF(P23="","",SUMIFS(Orders!$H$5:$H$154,Orders!$F$5:$F$154,P23,Orders!$B$5:$B$154,">="&$B$3,Orders!$B$5:$B$154,"<="&$E$3,Orders!$Q$5:$Q$154,"Paid",Orders!$R$5:$R$154,"Completed")) -> 0 | R23: =IF(P23="","",SUMIFS(Orders!$M$5:$M$154,Orders!$F$5:$F$154,P23,Orders!$B$5:$B$154,">="&$B$3,Orders!$B$5:$B$154,"<="&$E$3,Orders!$Q$5:$Q$154,"Paid",Orders!$R$5:$R$154,"Completed")) -> 0 | S23: =IF(P23="","",SUMIFS(Orders!$O$5:$O$154,Orders!$F$5:$F$154,P23,Orders!$B$5:$B$154,">="&$B$3,Orders!$B$5:$B$154,"<="&$E$3,Orders!$Q$5:$Q$154,"Paid",Orders!$R$5:$R$154,"Completed")) -> 0 | T23: =IF(P23="","",R23-S23) -> 0
A24: RECENT 14-DAY PERFORMANCE | P24: ='Menu & Pricing'!A25 -> 0 | Q24: =IF(P24="","",SUMIFS(Orders!$H$5:$H$154,Orders!$F$5:$F$154,P24,Orders!$B$5:$B$154,">="&$B$3,Orders!$B$5:$B$154,"<="&$E$3,Orders!$Q$5:$Q$154,"Paid",Orders!$R$5:$R$154,"Completed")) -> 0 | R24: =IF(P24="","",SUMIFS(Orders!$M$5:$M$154,Orders!$F$5:$F$154,P24,Orders!$B$5:$B$154,">="&$B$3,Orders!$B$5:$B$154,"<="&$E$3,Orders!$Q$5:$Q$154,"Paid",Orders!$R$5:$R$154,"Completed")) -> 0 | S24: =IF(P24="","",SUMIFS(Orders!$O$5:$O$154,Orders!$F$5:$F$154,P24,Orders!$B$5:$B$154,">="&$B$3,Orders!$B$5:$B$154,"<="&$E$3,Orders!$Q$5:$Q$154,"Paid",Orders!$R$5:$R$154,"Completed")) -> 0 | T24: =IF(P24="","",R24-S24) -> 0
P25: ='Menu & Pricing'!A26 -> 0 | Q25: =IF(P25="","",SUMIFS(Orders!$H$5:$H$154,Orders!$F$5:$F$154,P25,Orders!$B$5:$B$154,">="&$B$3,Orders!$B$5:$B$154,"<="&$E$3,Orders!$Q$5:$Q$154,"Paid",Orders!$R$5:$R$154,"Completed")) -> 0 | R25: =IF(P25="","",SUMIFS(Orders!$M$5:$M$154,Orders!$F$5:$F$154,P25,Orders!$B$5:$B$154,">="&$B$3,Orders!$B$5:$B$154,"<="&$E$3,Orders!$Q$5:$Q$154,"Paid",Orders!$R$5:$R$154,"Completed")) -> 0 | S25: =IF(P25="","",SUMIFS(Orders!$O$5:$O$154,Orders!$F$5:$F$154,P25,Orders!$B$5:$B$154,">="&$B$3,Orders!$B$5:$B$154,"<="&$E$3,Orders!$Q$5:$Q$154,"Paid",Orders!$R$5:$R$154,"Completed")) -> 0 | T25: =IF(P25="","",R25-S25) -> 0
A26: Date | B26: Net Sales (₱) | C26: Operating Expenses (₱) | D26: Net Profit (₱) | P26: ='Menu & Pricing'!A27 -> 0 | Q26: =IF(P26="","",SUMIFS(Orders!$H$5:$H$154,Orders!$F$5:$F$154,P26,Orders!$B$5:$B$154,">="&$B$3,Orders!$B$5:$B$154,"<="&$E$3,Orders!$Q$5:$Q$154,"Paid",Orders!$R$5:$R$154,"Completed")) -> 0 | R26: =IF(P26="","",SUMIFS(Orders!$M$5:$M$154,Orders!$F$5:$F$154,P26,Orders!$B$5:$B$154,">="&$B$3,Orders!$B$5:$B$154,"<="&$E$3,Orders!$Q$5:$Q$154,"Paid",Orders!$R$5:$R$154,"Completed")) -> 0 | S26: =IF(P26="","",SUMIFS(Orders!$O$5:$O$154,Orders!$F$5:$F$154,P26,Orders!$B$5:$B$154,">="&$B$3,Orders!$B$5:$B$154,"<="&$E$3,Orders!$Q$5:$Q$154,"Paid",Orders!$R$5:$R$154,"Completed")) -> 0 | T26: =IF(P26="","",R26-S26) -> 0 | U26: Date | V26: Net Sales (₱) | W26: Operating Expenses (₱) | X26: Net Profit (₱)
A27: =$E$3-13 -> 46203 | B27: =SUMIFS(Orders!$M$5:$M$154,Orders!$B$5:$B$154,A27,Orders!$Q$5:$Q$154,"Paid",Orders!$R$5:$R$154,"Completed") -> 0 | C27: =SUMIFS(Expenses!$J$5:$J$104,Expenses!$B$5:$B$104,A27,Expenses!$L$5:$L$104,"Operating Expense",Expenses!$M$5:$M$104,"Paid") -> 0 | D27: =B27-SUMIFS(Orders!$O$5:$O$154,Orders!$B$5:$B$154,A27,Orders!$Q$5:$Q$154,"Paid",Orders!$R$5:$R$154,"Completed")-C27 -> 0 | P27: ='Menu & Pricing'!A28 -> 0 | Q27: =IF(P27="","",SUMIFS(Orders!$H$5:$H$154,Orders!$F$5:$F$154,P27,Orders!$B$5:$B$154,">="&$B$3,Orders!$B$5:$B$154,"<="&$E$3,Orders!$Q$5:$Q$154,"Paid",Orders!$R$5:$R$154,"Completed")) -> 0 | R27: =IF(P27="","",SUMIFS(Orders!$M$5:$M$154,Orders!$F$5:$F$154,P27,Orders!$B$5:$B$154,">="&$B$3,Orders!$B$5:$B$154,"<="&$E$3,Orders!$Q$5:$Q$154,"Paid",Orders!$R$5:$R$154,"Completed")) -> 0 | S27: =IF(P27="","",SUMIFS(Orders!$O$5:$O$154,Orders!$F$5:$F$154,P27,Orders!$B$5:$B$154,">="&$B$3,Orders!$B$5:$B$154,"<="&$E$3,Orders!$Q$5:$Q$154,"Paid",Orders!$R$5:$R$154,"Completed")) -> 0 | T27: =IF(P27="","",R27-S27) -> 0 | U27: =TEXT(A27,"mmm d") -> Jun 30 | V27: =B27 -> 0 | W27: =C27 -> 0 | X27: =D27 -> 0
A28: =A27+1 -> 46204 | B28: =SUMIFS(Orders!$M$5:$M$154,Orders!$B$5:$B$154,A28,Orders!$Q$5:$Q$154,"Paid",Orders!$R$5:$R$154,"Completed") -> 0 | C28: =SUMIFS(Expenses!$J$5:$J$104,Expenses!$B$5:$B$104,A28,Expenses!$L$5:$L$104,"Operating Expense",Expenses!$M$5:$M$104,"Paid") -> 0 | D28: =B28-SUMIFS(Orders!$O$5:$O$154,Orders!$B$5:$B$154,A28,Orders!$Q$5:$Q$154,"Paid",Orders!$R$5:$R$154,"Completed")-C28 -> 0 | P28: ='Menu & Pricing'!A29 -> 0 | Q28: =IF(P28="","",SUMIFS(Orders!$H$5:$H$154,Orders!$F$5:$F$154,P28,Orders!$B$5:$B$154,">="&$B$3,Orders!$B$5:$B$154,"<="&$E$3,Orders!$Q$5:$Q$154,"Paid",Orders!$R$5:$R$154,"Completed")) -> 0 | R28: =IF(P28="","",SUMIFS(Orders!$M$5:$M$154,Orders!$F$5:$F$154,P28,Orders!$B$5:$B$154,">="&$B$3,Orders!$B$5:$B$154,"<="&$E$3,Orders!$Q$5:$Q$154,"Paid",Orders!$R$5:$R$154,"Completed")) -> 0 | S28: =IF(P28="","",SUMIFS(Orders!$O$5:$O$154,Orders!$F$5:$F$154,P28,Orders!$B$5:$B$154,">="&$B$3,Orders!$B$5:$B$154,"<="&$E$3,Orders!$Q$5:$Q$154,"Paid",Orders!$R$5:$R$154,"Completed")) -> 0 | T28: =IF(P28="","",R28-S28) -> 0 | U28: =TEXT(A28,"mmm d") -> Jul 1 | V28: =B28 -> 0 | W28: =C28 -> 0 | X28: =D28 -> 0
A29: =A28+1 -> 46205 | B29: =SUMIFS(Orders!$M$5:$M$154,Orders!$B$5:$B$154,A29,Orders!$Q$5:$Q$154,"Paid",Orders!$R$5:$R$154,"Completed") -> 0 | C29: =SUMIFS(Expenses!$J$5:$J$104,Expenses!$B$5:$B$104,A29,Expenses!$L$5:$L$104,"Operating Expense",Expenses!$M$5:$M$104,"Paid") -> 0 | D29: =B29-SUMIFS(Orders!$O$5:$O$154,Orders!$B$5:$B$154,A29,Orders!$Q$5:$Q$154,"Paid",Orders!$R$5:$R$154,"Completed")-C29 -> 0 | P29: ='Menu & Pricing'!A30 -> 0 | Q29: =IF(P29="","",SUMIFS(Orders!$H$5:$H$154,Orders!$F$5:$F$154,P29,Orders!$B$5:$B$154,">="&$B$3,Orders!$B$5:$B$154,"<="&$E$3,Orders!$Q$5:$Q$154,"Paid",Orders!$R$5:$R$154,"Completed")) -> 0 | R29: =IF(P29="","",SUMIFS(Orders!$M$5:$M$154,Orders!$F$5:$F$154,P29,Orders!$B$5:$B$154,">="&$B$3,Orders!$B$5:$B$154,"<="&$E$3,Orders!$Q$5:$Q$154,"Paid",Orders!$R$5:$R$154,"Completed")) -> 0 | S29: =IF(P29="","",SUMIFS(Orders!$O$5:$O$154,Orders!$F$5:$F$154,P29,Orders!$B$5:$B$154,">="&$B$3,Orders!$B$5:$B$154,"<="&$E$3,Orders!$Q$5:$Q$154,"Paid",Orders!$R$5:$R$154,"Completed")) -> 0 | T29: =IF(P29="","",R29-S29) -> 0 | U29: =TEXT(A29,"mmm d") -> Jul 2 | V29: =B29 -> 0 | W29: =C29 -> 0 | X29: =D29 -> 0
A30: =A29+1 -> 46206 | B30: =SUMIFS(Orders!$M$5:$M$154,Orders!$B$5:$B$154,A30,Orders!$Q$5:$Q$154,"Paid",Orders!$R$5:$R$154,"Completed") -> 0 | C30: =SUMIFS(Expenses!$J$5:$J$104,Expenses!$B$5:$B$104,A30,Expenses!$L$5:$L$104,"Operating Expense",Expenses!$M$5:$M$104,"Paid") -> 0 | D30: =B30-SUMIFS(Orders!$O$5:$O$154,Orders!$B$5:$B$154,A30,Orders!$Q$5:$Q$154,"Paid",Orders!$R$5:$R$154,"Completed")-C30 -> 0 | P30: ='Menu & Pricing'!A31 -> 0 | Q30: =IF(P30="","",SUMIFS(Orders!$H$5:$H$154,Orders!$F$5:$F$154,P30,Orders!$B$5:$B$154,">="&$B$3,Orders!$B$5:$B$154,"<="&$E$3,Orders!$Q$5:$Q$154,"Paid",Orders!$R$5:$R$154,"Completed")) -> 0 | R30: =IF(P30="","",SUMIFS(Orders!$M$5:$M$154,Orders!$F$5:$F$154,P30,Orders!$B$5:$B$154,">="&$B$3,Orders!$B$5:$B$154,"<="&$E$3,Orders!$Q$5:$Q$154,"Paid",Orders!$R$5:$R$154,"Completed")) -> 0 | S30: =IF(P30="","",SUMIFS(Orders!$O$5:$O$154,Orders!$F$5:$F$154,P30,Orders!$B$5:$B$154,">="&$B$3,Orders!$B$5:$B$154,"<="&$E$3,Orders!$Q$5:$Q$154,"Paid",Orders!$R$5:$R$154,"Completed")) -> 0 | T30: =IF(P30="","",R30-S30) -> 0 | U30: =TEXT(A30,"mmm d") -> Jul 3 | V30: =B30 -> 0 | W30: =C30 -> 0 | X30: =D30 -> 0
A31: =A30+1 -> 46207 | B31: =SUMIFS(Orders!$M$5:$M$154,Orders!$B$5:$B$154,A31,Orders!$Q$5:$Q$154,"Paid",Orders!$R$5:$R$154,"Completed") -> 0 | C31: =SUMIFS(Expenses!$J$5:$J$104,Expenses!$B$5:$B$104,A31,Expenses!$L$5:$L$104,"Operating Expense",Expenses!$M$5:$M$104,"Paid") -> 0 | D31: =B31-SUMIFS(Orders!$O$5:$O$154,Orders!$B$5:$B$154,A31,Orders!$Q$5:$Q$154,"Paid",Orders!$R$5:$R$154,"Completed")-C31 -> 0 | P31: ='Menu & Pricing'!A32 -> 0 | Q31: =IF(P31="","",SUMIFS(Orders!$H$5:$H$154,Orders!$F$5:$F$154,P31,Orders!$B$5:$B$154,">="&$B$3,Orders!$B$5:$B$154,"<="&$E$3,Orders!$Q$5:$Q$154,"Paid",Orders!$R$5:$R$154,"Completed")) -> 0 | R31: =IF(P31="","",SUMIFS(Orders!$M$5:$M$154,Orders!$F$5:$F$154,P31,Orders!$B$5:$B$154,">="&$B$3,Orders!$B$5:$B$154,"<="&$E$3,Orders!$Q$5:$Q$154,"Paid",Orders!$R$5:$R$154,"Completed")) -> 0 | S31: =IF(P31="","",SUMIFS(Orders!$O$5:$O$154,Orders!$F$5:$F$154,P31,Orders!$B$5:$B$154,">="&$B$3,Orders!$B$5:$B$154,"<="&$E$3,Orders!$Q$5:$Q$154,"Paid",Orders!$R$5:$R$154,"Completed")) -> 0 | T31: =IF(P31="","",R31-S31) -> 0 | U31: =TEXT(A31,"mmm d") -> Jul 4 | V31: =B31 -> 0 | W31: =C31 -> 0 | X31: =D31 -> 0
A32: =A31+1 -> 46208 | B32: =SUMIFS(Orders!$M$5:$M$154,Orders!$B$5:$B$154,A32,Orders!$Q$5:$Q$154,"Paid",Orders!$R$5:$R$154,"Completed") -> 0 | C32: =SUMIFS(Expenses!$J$5:$J$104,Expenses!$B$5:$B$104,A32,Expenses!$L$5:$L$104,"Operating Expense",Expenses!$M$5:$M$104,"Paid") -> 0 | D32: =B32-SUMIFS(Orders!$O$5:$O$154,Orders!$B$5:$B$154,A32,Orders!$Q$5:$Q$154,"Paid",Orders!$R$5:$R$154,"Completed")-C32 -> 0 | P32: ='Menu & Pricing'!A33 -> 0 | Q32: =IF(P32="","",SUMIFS(Orders!$H$5:$H$154,Orders!$F$5:$F$154,P32,Orders!$B$5:$B$154,">="&$B$3,Orders!$B$5:$B$154,"<="&$E$3,Orders!$Q$5:$Q$154,"Paid",Orders!$R$5:$R$154,"Completed")) -> 0 | R32: =IF(P32="","",SUMIFS(Orders!$M$5:$M$154,Orders!$F$5:$F$154,P32,Orders!$B$5:$B$154,">="&$B$3,Orders!$B$5:$B$154,"<="&$E$3,Orders!$Q$5:$Q$154,"Paid",Orders!$R$5:$R$154,"Completed")) -> 0 | S32: =IF(P32="","",SUMIFS(Orders!$O$5:$O$154,Orders!$F$5:$F$154,P32,Orders!$B$5:$B$154,">="&$B$3,Orders!$B$5:$B$154,"<="&$E$3,Orders!$Q$5:$Q$154,"Paid",Orders!$R$5:$R$154,"Completed")) -> 0 | T32: =IF(P32="","",R32-S32) -> 0 | U32: =TEXT(A32,"mmm d") -> Jul 5 | V32: =B32 -> 0 | W32: =C32 -> 0 | X32: =D32 -> 0
A33: =A32+1 -> 46209 | B33: =SUMIFS(Orders!$M$5:$M$154,Orders!$B$5:$B$154,A33,Orders!$Q$5:$Q$154,"Paid",Orders!$R$5:$R$154,"Completed") -> 0 | C33: =SUMIFS(Expenses!$J$5:$J$104,Expenses!$B$5:$B$104,A33,Expenses!$L$5:$L$104,"Operating Expense",Expenses!$M$5:$M$104,"Paid") -> 0 | D33: =B33-SUMIFS(Orders!$O$5:$O$154,Orders!$B$5:$B$154,A33,Orders!$Q$5:$Q$154,"Paid",Orders!$R$5:$R$154,"Completed")-C33 -> 0 | P33: ='Menu & Pricing'!A34 -> 0 | Q33: =IF(P33="","",SUMIFS(Orders!$H$5:$H$154,Orders!$F$5:$F$154,P33,Orders!$B$5:$B$154,">="&$B$3,Orders!$B$5:$B$154,"<="&$E$3,Orders!$Q$5:$Q$154,"Paid",Orders!$R$5:$R$154,"Completed")) -> 0 | R33: =IF(P33="","",SUMIFS(Orders!$M$5:$M$154,Orders!$F$5:$F$154,P33,Orders!$B$5:$B$154,">="&$B$3,Orders!$B$5:$B$154,"<="&$E$3,Orders!$Q$5:$Q$154,"Paid",Orders!$R$5:$R$154,"Completed")) -> 0 | S33: =IF(P33="","",SUMIFS(Orders!$O$5:$O$154,Orders!$F$5:$F$154,P33,Orders!$B$5:$B$154,">="&$B$3,Orders!$B$5:$B$154,"<="&$E$3,Orders!$Q$5:$Q$154,"Paid",Orders!$R$5:$R$154,"Completed")) -> 0 | T33: =IF(P33="","",R33-S33) -> 0 | U33: =TEXT(A33,"mmm d") -> Jul 6 | V33: =B33 -> 0 | W33: =C33 -> 0 | X33: =D33 -> 0
A34: =A33+1 -> 46210 | B34: =SUMIFS(Orders!$M$5:$M$154,Orders!$B$5:$B$154,A34,Orders!$Q$5:$Q$154,"Paid",Orders!$R$5:$R$154,"Completed") -> 0 | C34: =SUMIFS(Expenses!$J$5:$J$104,Expenses!$B$5:$B$104,A34,Expenses!$L$5:$L$104,"Operating Expense",Expenses!$M$5:$M$104,"Paid") -> 0 | D34: =B34-SUMIFS(Orders!$O$5:$O$154,Orders!$B$5:$B$154,A34,Orders!$Q$5:$Q$154,"Paid",Orders!$R$5:$R$154,"Completed")-C34 -> 0 | P34: ='Menu & Pricing'!A35 -> 0 | Q34: =IF(P34="","",SUMIFS(Orders!$H$5:$H$154,Orders!$F$5:$F$154,P34,Orders!$B$5:$B$154,">="&$B$3,Orders!$B$5:$B$154,"<="&$E$3,Orders!$Q$5:$Q$154,"Paid",Orders!$R$5:$R$154,"Completed")) -> 0 | R34: =IF(P34="","",SUMIFS(Orders!$M$5:$M$154,Orders!$F$5:$F$154,P34,Orders!$B$5:$B$154,">="&$B$3,Orders!$B$5:$B$154,"<="&$E$3,Orders!$Q$5:$Q$154,"Paid",Orders!$R$5:$R$154,"Completed")) -> 0 | S34: =IF(P34="","",SUMIFS(Orders!$O$5:$O$154,Orders!$F$5:$F$154,P34,Orders!$B$5:$B$154,">="&$B$3,Orders!$B$5:$B$154,"<="&$E$3,Orders!$Q$5:$Q$154,"Paid",Orders!$R$5:$R$154,"Completed")) -> 0 | T34: =IF(P34="","",R34-S34) -> 0 | U34: =TEXT(A34,"mmm d") -> Jul 7 | V34: =B34 -> 0 | W34: =C34 -> 0 | X34: =D34 -> 0
A35: =A34+1 -> 46211 | B35: =SUMIFS(Orders!$M$5:$M$154,Orders!$B$5:$B$154,A35,Orders!$Q$5:$Q$154,"Paid",Orders!$R$5:$R$154,"Completed") -> 0 | C35: =SUMIFS(Expenses!$J$5:$J$104,Expenses!$B$5:$B$104,A35,Expenses!$L$5:$L$104,"Operating Expense",Expenses!$M$5:$M$104,"Paid") -> 0 | D35: =B35-SUMIFS(Orders!$O$5:$O$154,Orders!$B$5:$B$154,A35,Orders!$Q$5:$Q$154,"Paid",Orders!$R$5:$R$154,"Completed")-C35 -> 0 | P35: ='Menu & Pricing'!A36 -> 0 | Q35: =IF(P35="","",SUMIFS(Orders!$H$5:$H$154,Orders!$F$5:$F$154,P35,Orders!$B$5:$B$154,">="&$B$3,Orders!$B$5:$B$154,"<="&$E$3,Orders!$Q$5:$Q$154,"Paid",Orders!$R$5:$R$154,"Completed")) -> 0 | R35: =IF(P35="","",SUMIFS(Orders!$M$5:$M$154,Orders!$F$5:$F$154,P35,Orders!$B$5:$B$154,">="&$B$3,Orders!$B$5:$B$154,"<="&$E$3,Orders!$Q$5:$Q$154,"Paid",Orders!$R$5:$R$154,"Completed")) -> 0 | S35: =IF(P35="","",SUMIFS(Orders!$O$5:$O$154,Orders!$F$5:$F$154,P35,Orders!$B$5:$B$154,">="&$B$3,Orders!$B$5:$B$154,"<="&$E$3,Orders!$Q$5:$Q$154,"Paid",Orders!$R$5:$R$154,"Completed")) -> 0 | T35: =IF(P35="","",R35-S35) -> 0 | U35: =TEXT(A35,"mmm d") -> Jul 8 | V35: =B35 -> 0 | W35: =C35 -> 0 | X35: =D35 -> 0
A36: =A35+1 -> 46212 | B36: =SUMIFS(Orders!$M$5:$M$154,Orders!$B$5:$B$154,A36,Orders!$Q$5:$Q$154,"Paid",Orders!$R$5:$R$154,"Completed") -> 0 | C36: =SUMIFS(Expenses!$J$5:$J$104,Expenses!$B$5:$B$104,A36,Expenses!$L$5:$L$104,"Operating Expense",Expenses!$M$5:$M$104,"Paid") -> 0 | D36: =B36-SUMIFS(Orders!$O$5:$O$154,Orders!$B$5:$B$154,A36,Orders!$Q$5:$Q$154,"Paid",Orders!$R$5:$R$154,"Completed")-C36 -> 0 | P36: ='Menu & Pricing'!A37 -> 0 | Q36: =IF(P36="","",SUMIFS(Orders!$H$5:$H$154,Orders!$F$5:$F$154,P36,Orders!$B$5:$B$154,">="&$B$3,Orders!$B$5:$B$154,"<="&$E$3,Orders!$Q$5:$Q$154,"Paid",Orders!$R$5:$R$154,"Completed")) -> 0 | R36: =IF(P36="","",SUMIFS(Orders!$M$5:$M$154,Orders!$F$5:$F$154,P36,Orders!$B$5:$B$154,">="&$B$3,Orders!$B$5:$B$154,"<="&$E$3,Orders!$Q$5:$Q$154,"Paid",Orders!$R$5:$R$154,"Completed")) -> 0 | S36: =IF(P36="","",SUMIFS(Orders!$O$5:$O$154,Orders!$F$5:$F$154,P36,Orders!$B$5:$B$154,">="&$B$3,Orders!$B$5:$B$154,"<="&$E$3,Orders!$Q$5:$Q$154,"Paid",Orders!$R$5:$R$154,"Completed")) -> 0 | T36: =IF(P36="","",R36-S36) -> 0 | U36: =TEXT(A36,"mmm d") -> Jul 9 | V36: =B36 -> 0 | W36: =C36 -> 0 | X36: =D36 -> 0
A37: =A36+1 -> 46213 | B37: =SUMIFS(Orders!$M$5:$M$154,Orders!$B$5:$B$154,A37,Orders!$Q$5:$Q$154,"Paid",Orders!$R$5:$R$154,"Completed") -> 0 | C37: =SUMIFS(Expenses!$J$5:$J$104,Expenses!$B$5:$B$104,A37,Expenses!$L$5:$L$104,"Operating Expense",Expenses!$M$5:$M$104,"Paid") -> 0 | D37: =B37-SUMIFS(Orders!$O$5:$O$154,Orders!$B$5:$B$154,A37,Orders!$Q$5:$Q$154,"Paid",Orders!$R$5:$R$154,"Completed")-C37 -> 0 | P37: ='Menu & Pricing'!A38 -> 0 | Q37: =IF(P37="","",SUMIFS(Orders!$H$5:$H$154,Orders!$F$5:$F$154,P37,Orders!$B$5:$B$154,">="&$B$3,Orders!$B$5:$B$154,"<="&$E$3,Orders!$Q$5:$Q$154,"Paid",Orders!$R$5:$R$154,"Completed")) -> 0 | R37: =IF(P37="","",SUMIFS(Orders!$M$5:$M$154,Orders!$F$5:$F$154,P37,Orders!$B$5:$B$154,">="&$B$3,Orders!$B$5:$B$154,"<="&$E$3,Orders!$Q$5:$Q$154,"Paid",Orders!$R$5:$R$154,"Completed")) -> 0 | S37: =IF(P37="","",SUMIFS(Orders!$O$5:$O$154,Orders!$F$5:$F$154,P37,Orders!$B$5:$B$154,">="&$B$3,Orders!$B$5:$B$154,"<="&$E$3,Orders!$Q$5:$Q$154,"Paid",Orders!$R$5:$R$154,"Completed")) -> 0 | T37: =IF(P37="","",R37-S37) -> 0 | U37: =TEXT(A37,"mmm d") -> Jul 10 | V37: =B37 -> 0 | W37: =C37 -> 0 | X37: =D37 -> 0
A38: =A37+1 -> 46214 | B38: =SUMIFS(Orders!$M$5:$M$154,Orders!$B$5:$B$154,A38,Orders!$Q$5:$Q$154,"Paid",Orders!$R$5:$R$154,"Completed") -> 0 | C38: =SUMIFS(Expenses!$J$5:$J$104,Expenses!$B$5:$B$104,A38,Expenses!$L$5:$L$104,"Operating Expense",Expenses!$M$5:$M$104,"Paid") -> 0 | D38: =B38-SUMIFS(Orders!$O$5:$O$154,Orders!$B$5:$B$154,A38,Orders!$Q$5:$Q$154,"Paid",Orders!$R$5:$R$154,"Completed")-C38 -> 0 | P38: ='Menu & Pricing'!A39 -> 0 | Q38: =IF(P38="","",SUMIFS(Orders!$H$5:$H$154,Orders!$F$5:$F$154,P38,Orders!$B$5:$B$154,">="&$B$3,Orders!$B$5:$B$154,"<="&$E$3,Orders!$Q$5:$Q$154,"Paid",Orders!$R$5:$R$154,"Completed")) -> 0 | R38: =IF(P38="","",SUMIFS(Orders!$M$5:$M$154,Orders!$F$5:$F$154,P38,Orders!$B$5:$B$154,">="&$B$3,Orders!$B$5:$B$154,"<="&$E$3,Orders!$Q$5:$Q$154,"Paid",Orders!$R$5:$R$154,"Completed")) -> 0 | S38: =IF(P38="","",SUMIFS(Orders!$O$5:$O$154,Orders!$F$5:$F$154,P38,Orders!$B$5:$B$154,">="&$B$3,Orders!$B$5:$B$154,"<="&$E$3,Orders!$Q$5:$Q$154,"Paid",Orders!$R$5:$R$154,"Completed")) -> 0 | T38: =IF(P38="","",R38-S38) -> 0 | U38: =TEXT(A38,"mmm d") -> Jul 11 | V38: =B38 -> 0 | W38: =C38 -> 0 | X38: =D38 -> 0
A39: =A38+1 -> 46215 | B39: =SUMIFS(Orders!$M$5:$M$154,Orders!$B$5:$B$154,A39,Orders!$Q$5:$Q$154,"Paid",Orders!$R$5:$R$154,"Completed") -> 0 | C39: =SUMIFS(Expenses!$J$5:$J$104,Expenses!$B$5:$B$104,A39,Expenses!$L$5:$L$104,"Operating Expense",Expenses!$M$5:$M$104,"Paid") -> 0 | D39: =B39-SUMIFS(Orders!$O$5:$O$154,Orders!$B$5:$B$154,A39,Orders!$Q$5:$Q$154,"Paid",Orders!$R$5:$R$154,"Completed")-C39 -> 0 | P39: ='Menu & Pricing'!A40 -> 0 | Q39: =IF(P39="","",SUMIFS(Orders!$H$5:$H$154,Orders!$F$5:$F$154,P39,Orders!$B$5:$B$154,">="&$B$3,Orders!$B$5:$B$154,"<="&$E$3,Orders!$Q$5:$Q$154,"Paid",Orders!$R$5:$R$154,"Completed")) -> 0 | R39: =IF(P39="","",SUMIFS(Orders!$M$5:$M$154,Orders!$F$5:$F$154,P39,Orders!$B$5:$B$154,">="&$B$3,Orders!$B$5:$B$154,"<="&$E$3,Orders!$Q$5:$Q$154,"Paid",Orders!$R$5:$R$154,"Completed")) -> 0 | S39: =IF(P39="","",SUMIFS(Orders!$O$5:$O$154,Orders!$F$5:$F$154,P39,Orders!$B$5:$B$154,">="&$B$3,Orders!$B$5:$B$154,"<="&$E$3,Orders!$Q$5:$Q$154,"Paid",Orders!$R$5:$R$154,"Completed")) -> 0 | T39: =IF(P39="","",R39-S39) -> 0 | U39: =TEXT(A39,"mmm d") -> Jul 12 | V39: =B39 -> 0 | W39: =C39 -> 0 | X39: =D39 -> 0
A40: =A39+1 -> 46216 | B40: =SUMIFS(Orders!$M$5:$M$154,Orders!$B$5:$B$154,A40,Orders!$Q$5:$Q$154,"Paid",Orders!$R$5:$R$154,"Completed") -> 0 | C40: =SUMIFS(Expenses!$J$5:$J$104,Expenses!$B$5:$B$104,A40,Expenses!$L$5:$L$104,"Operating Expense",Expenses!$M$5:$M$104,"Paid") -> 0 | D40: =B40-SUMIFS(Orders!$O$5:$O$154,Orders!$B$5:$B$154,A40,Orders!$Q$5:$Q$154,"Paid",Orders!$R$5:$R$154,"Completed")-C40 -> 0 | P40: ='Menu & Pricing'!A41 -> 0 | Q40: =IF(P40="","",SUMIFS(Orders!$H$5:$H$154,Orders!$F$5:$F$154,P40,Orders!$B$5:$B$154,">="&$B$3,Orders!$B$5:$B$154,"<="&$E$3,Orders!$Q$5:$Q$154,"Paid",Orders!$R$5:$R$154,"Completed")) -> 0 | R40: =IF(P40="","",SUMIFS(Orders!$M$5:$M$154,Orders!$F$5:$F$154,P40,Orders!$B$5:$B$154,">="&$B$3,Orders!$B$5:$B$154,"<="&$E$3,Orders!$Q$5:$Q$154,"Paid",Orders!$R$5:$R$154,"Completed")) -> 0 | S40: =IF(P40="","",SUMIFS(Orders!$O$5:$O$154,Orders!$F$5:$F$154,P40,Orders!$B$5:$B$154,">="&$B$3,Orders!$B$5:$B$154,"<="&$E$3,Orders!$Q$5:$Q$154,"Paid",Orders!$R$5:$R$154,"Completed")) -> 0 | T40: =IF(P40="","",R40-S40) -> 0 | U40: =TEXT(A40,"mmm d") -> Jul 13 | V40: =B40 -> 0 | W40: =C40 -> 0 | X40: =D40 -> 0
P41: ='Menu & Pricing'!A42 -> 0 | Q41: =IF(P41="","",SUMIFS(Orders!$H$5:$H$154,Orders!$F$5:$F$154,P41,Orders!$B$5:$B$154,">="&$B$3,Orders!$B$5:$B$154,"<="&$E$3,Orders!$Q$5:$Q$154,"Paid",Orders!$R$5:$R$154,"Completed")) -> 0 | R41: =IF(P41="","",SUMIFS(Orders!$M$5:$M$154,Orders!$F$5:$F$154,P41,Orders!$B$5:$B$154,">="&$B$3,Orders!$B$5:$B$154,"<="&$E$3,Orders!$Q$5:$Q$154,"Paid",Orders!$R$5:$R$154,"Completed")) -> 0 | S41: =IF(P41="","",SUMIFS(Orders!$O$5:$O$154,Orders!$F$5:$F$154,P41,Orders!$B$5:$B$154,">="&$B$3,Orders!$B$5:$B$154,"<="&$E$3,Orders!$Q$5:$Q$154,"Paid",Orders!$R$5:$R$154,"Completed")) -> 0 | T41: =IF(P41="","",R41-S41) -> 0
...

Sheet Orders
A1: ORDERS TRACKER
A2: One row per item sold. For one order with multiple items, repeat the same Order ID and date.
A4: Order ID | B4: Date | C4: Time | D4: Customer Name | E4: Order Type | F4: Menu Item / Variant | G4: Category | H4: Quantity | I4: Unit Price (₱) | J4: Add-on Charges (₱) | K4: Gross Sales (₱) | L4: Discount (₱) | M4: Net Sales (₱) | N4: Est. Unit Cost (₱) | O4: Est. COGS (₱) | P4: Payment Method | Q4: Payment Status | R4: Order Status | S4: Staff / Cashier | T4: Notes | U4: Order Count Helper
G5: =IFERROR(VLOOKUP(F5,'Menu & Pricing'!$A$5:$I$54,2,FALSE),"") | I5: =IFERROR(VLOOKUP(F5,'Menu & Pricing'!$A$5:$I$54,5,FALSE),"") | K5: =IF(OR(H5="",I5=""),"",H5*I5+IF(J5="",0,J5)) | M5: =IF(K5="","",MAX(0,K5-IF(L5="",0,L5))) | N5: =IFERROR(VLOOKUP(F5,'Menu & Pricing'!$A$5:$I$54,6,FALSE),"") | O5: =IF(OR(H5="",N5=""),"",H5*N5) | U5: =IF(AND(A5<>"",Q5="Paid",R5="Completed",COUNTIFS($A$5:A5,A5,$B$5:B5,B5,$Q$5:Q5,"Paid",$R$5:R5,"Completed")=1),1,0) -> 0
G6: =IFERROR(VLOOKUP(F6,'Menu & Pricing'!$A$5:$I$54,2,FALSE),"") | I6: =IFERROR(VLOOKUP(F6,'Menu & Pricing'!$A$5:$I$54,5,FALSE),"") | K6: =IF(OR(H6="",I6=""),"",H6*I6+IF(J6="",0,J6)) | M6: =IF(K6="","",MAX(0,K6-IF(L6="",0,L6))) | N6: =IFERROR(VLOOKUP(F6,'Menu & Pricing'!$A$5:$I$54,6,FALSE),"") | O6: =IF(OR(H6="",N6=""),"",H6*N6) | U6: =IF(AND(A6<>"",Q6="Paid",R6="Completed",COUNTIFS($A$5:A6,A6,$B$5:B6,B6,$Q$5:Q6,"Paid",$R$5:R6,"Completed")=1),1,0) -> 0
G7: =IFERROR(VLOOKUP(F7,'Menu & Pricing'!$A$5:$I$54,2,FALSE),"") | I7: =IFERROR(VLOOKUP(F7,'Menu & Pricing'!$A$5:$I$54,5,FALSE),"") | K7: =IF(OR(H7="",I7=""),"",H7*I7+IF(J7="",0,J7)) | M7: =IF(K7="","",MAX(0,K7-IF(L7="",0,L7))) | N7: =IFERROR(VLOOKUP(F7,'Menu & Pricing'!$A$5:$I$54,6,FALSE),"") | O7: =IF(OR(H7="",N7=""),"",H7*N7) | U7: =IF(AND(A7<>"",Q7="Paid",R7="Completed",COUNTIFS($A$5:A7,A7,$B$5:B7,B7,$Q$5:Q7,"Paid",$R$5:R7,"Completed")=1),1,0) -> 0
G8: =IFERROR(VLOOKUP(F8,'Menu & Pricing'!$A$5:$I$54,2,FALSE),"") | I8: =IFERROR(VLOOKUP(F8,'Menu & Pricing'!$A$5:$I$54,5,FALSE),"") | K8: =IF(OR(H8="",I8=""),"",H8*I8+IF(J8="",0,J8)) | M8: =IF(K8="","",MAX(0,K8-IF(L8="",0,L8))) | N8: =IFERROR(VLOOKUP(F8,'Menu & Pricing'!$A$5:$I$54,6,FALSE),"") | O8: =IF(OR(H8="",N8=""),"",H8*N8) | U8: =IF(AND(A8<>"",Q8="Paid",R8="Completed",COUNTIFS($A$5:A8,A8,$B$5:B8,B8,$Q$5:Q8,"Paid",$R$5:R8,"Completed")=1),1,0) -> 0
G9: =IFERROR(VLOOKUP(F9,'Menu & Pricing'!$A$5:$I$54,2,FALSE),"") | I9: =IFERROR(VLOOKUP(F9,'Menu & Pricing'!$A$5:$I$54,5,FALSE),"") | K9: =IF(OR(H9="",I9=""),"",H9*I9+IF(J9="",0,J9)) | M9: =IF(K9="","",MAX(0,K9-IF(L9="",0,L9))) | N9: =IFERROR(VLOOKUP(F9,'Menu & Pricing'!$A$5:$I$54,6,FALSE),"") | O9: =IF(OR(H9="",N9=""),"",H9*N9) | U9: =IF(AND(A9<>"",Q9="Paid",R9="Completed",COUNTIFS($A$5:A9,A9,$B$5:B9,B9,$Q$5:Q9,"Paid",$R$5:R9,"Completed")=1),1,0) -> 0
G10: =IFERROR(VLOOKUP(F10,'Menu & Pricing'!$A$5:$I$54,2,FALSE),"") | I10: =IFERROR(VLOOKUP(F10,'Menu & Pricing'!$A$5:$I$54,5,FALSE),"") | K10: =IF(OR(H10="",I10=""),"",H10*I10+IF(J10="",0,J10)) | M10: =IF(K10="","",MAX(0,K10-IF(L10="",0,L10))) | N10: =IFERROR(VLOOKUP(F10,'Menu & Pricing'!$A$5:$I$54,6,FALSE),"") | O10: =IF(OR(H10="",N10=""),"",H10*N10) | U10: =IF(AND(A10<>"",Q10="Paid",R10="Completed",COUNTIFS($A$5:A10,A10,$B$5:B10,B10,$Q$5:Q10,"Paid",$R$5:R10,"Completed")=1),1,0) -> 0
G11: =IFERROR(VLOOKUP(F11,'Menu & Pricing'!$A$5:$I$54,2,FALSE),"") | I11: =IFERROR(VLOOKUP(F11,'Menu & Pricing'!$A$5:$I$54,5,FALSE),"") | K11: =IF(OR(H11="",I11=""),"",H11*I11+IF(J11="",0,J11)) | M11: =IF(K11="","",MAX(0,K11-IF(L11="",0,L11))) | N11: =IFERROR(VLOOKUP(F11,'Menu & Pricing'!$A$5:$I$54,6,FALSE),"") | O11: =IF(OR(H11="",N11=""),"",H11*N11) | U11: =IF(AND(A11<>"",Q11="Paid",R11="Completed",COUNTIFS($A$5:A11,A11,$B$5:B11,B11,$Q$5:Q11,"Paid",$R$5:R11,"Completed")=1),1,0) -> 0
G12: =IFERROR(VLOOKUP(F12,'Menu & Pricing'!$A$5:$I$54,2,FALSE),"") | I12: =IFERROR(VLOOKUP(F12,'Menu & Pricing'!$A$5:$I$54,5,FALSE),"") | K12: =IF(OR(H12="",I12=""),"",H12*I12+IF(J12="",0,J12)) | M12: =IF(K12="","",MAX(0,K12-IF(L12="",0,L12))) | N12: =IFERROR(VLOOKUP(F12,'Menu & Pricing'!$A$5:$I$54,6,FALSE),"") | O12: =IF(OR(H12="",N12=""),"",H12*N12) | U12: =IF(AND(A12<>"",Q12="Paid",R12="Completed",COUNTIFS($A$5:A12,A12,$B$5:B12,B12,$Q$5:Q12,"Paid",$R$5:R12,"Completed")=1),1,0) -> 0
G13: =IFERROR(VLOOKUP(F13,'Menu & Pricing'!$A$5:$I$54,2,FALSE),"") | I13: =IFERROR(VLOOKUP(F13,'Menu & Pricing'!$A$5:$I$54,5,FALSE),"") | K13: =IF(OR(H13="",I13=""),"",H13*I13+IF(J13="",0,J13)) | M13: =IF(K13="","",MAX(0,K13-IF(L13="",0,L13))) | N13: =IFERROR(VLOOKUP(F13,'Menu & Pricing'!$A$5:$I$54,6,FALSE),"") | O13: =IF(OR(H13="",N13=""),"",H13*N13) | U13: =IF(AND(A13<>"",Q13="Paid",R13="Completed",COUNTIFS($A$5:A13,A13,$B$5:B13,B13,$Q$5:Q13,"Paid",$R$5:R13,"Completed")=1),1,0) -> 0
G14: =IFERROR(VLOOKUP(F14,'Menu & Pricing'!$A$5:$I$54,2,FALSE),"") | I14: =IFERROR(VLOOKUP(F14,'Menu & Pricing'!$A$5:$I$54,5,FALSE),"") | K14: =IF(OR(H14="",I14=""),"",H14*I14+IF(J14="",0,J14)) | M14: =IF(K14="","",MAX(0,K14-IF(L14="",0,L14))) | N14: =IFERROR(VLOOKUP(F14,'Menu & Pricing'!$A$5:$I$54,6,FALSE),"") | O14: =IF(OR(H14="",N14=""),"",H14*N14) | U14: =IF(AND(A14<>"",Q14="Paid",R14="Completed",COUNTIFS($A$5:A14,A14,$B$5:B14,B14,$Q$5:Q14,"Paid",$R$5:R14,"Completed")=1),1,0) -> 0
G15: =IFERROR(VLOOKUP(F15,'Menu & Pricing'!$A$5:$I$54,2,FALSE),"") | I15: =IFERROR(VLOOKUP(F15,'Menu & Pricing'!$A$5:$I$54,5,FALSE),"") | K15: =IF(OR(H15="",I15=""),"",H15*I15+IF(J15="",0,J15)) | M15: =IF(K15="","",MAX(0,K15-IF(L15="",0,L15))) | N15: =IFERROR(VLOOKUP(F15,'Menu & Pricing'!$A$5:$I$54,6,FALSE),"") | O15: =IF(OR(H15="",N15=""),"",H15*N15) | U15: =IF(AND(A15<>"",Q15="Paid",R15="Completed",COUNTIFS($A$5:A15,A15,$B$5:B15,B15,$Q$5:Q15,"Paid",$R$5:R15,"Completed")=1),1,0) -> 0
G16: =IFERROR(VLOOKUP(F16,'Menu & Pricing'!$A$5:$I$54,2,FALSE),"") | I16: =IFERROR(VLOOKUP(F16,'Menu & Pricing'!$A$5:$I$54,5,FALSE),"") | K16: =IF(OR(H16="",I16=""),"",H16*I16+IF(J16="",0,J16)) | M16: =IF(K16="","",MAX(0,K16-IF(L16="",0,L16))) | N16: =IFERROR(VLOOKUP(F16,'Menu & Pricing'!$A$5:$I$54,6,FALSE),"") | O16: =IF(OR(H16="",N16=""),"",H16*N16) | U16: =IF(AND(A16<>"",Q16="Paid",R16="Completed",COUNTIFS($A$5:A16,A16,$B$5:B16,B16,$Q$5:Q16,"Paid",$R$5:R16,"Completed")=1),1,0) -> 0
... G154: =IFERROR(VLOOKUP(F154,'Menu & Pricing'!$A$5:$I$54,2,FALSE),"") | I154: =IFERROR(VLOOKUP(F154,'Menu & Pricing'!$A$5:$I$54,5,FALSE),"") | K154: =IF(OR(H154="",I154=""),"",H154*I154+IF(J154="",0,J154)) | M154: =IF(K154="","",MAX(0,K154-IF(L154="",0,L154))) | N154: =IFERROR(VLOOKUP(F154,'Menu & Pricing'!$A$5:$I$54,6,FALSE),"") | O154: =IF(OR(H154="",N154=""),"",H154*N154) | U154: =IF(AND(A154<>"",Q154="Paid",R154="Completed",COUNTIFS($A$5:A154,A154,$B$5:B154,B154,$Q$5:Q154,"Paid",$R$5:R154,"Completed")=1),1,0) -> 0

Sheet Expenses
A1: EXPENSES TRACKER
A2: Operating Expenses affect net profit. Inventory and capital purchases still appear as paid cash out.
A4: Expense ID | B4: Date | C4: Time | D4: Expense Category | E4: Item / Description | F4: Supplier | G4: Quantity | H4: Unit | I4: Unit Cost (₱) | J4: Total Expense (₱) | K4: Payment Method | L4: Expense Type | M4: Status | N4: Paid By | O4: Receipt No. | P4: Notes
J5: =IF(OR(G5="",I5=""),"",G5*I5)
J6: =IF(OR(G6="",I6=""),"",G6*I6)
J7: =IF(OR(G7="",I7=""),"",G7*I7)
J8: =IF(OR(G8="",I8=""),"",G8*I8)
J9: =IF(OR(G9="",I9=""),"",G9*I9)
J10: =IF(OR(G10="",I10=""),"",G10*I10)
J11: =IF(OR(G11="",I11=""),"",G11*I11)
J12: =IF(OR(G12="",I12=""),"",G12*I12)
J13: =IF(OR(G13="",I13=""),"",G13*I13)
J14: =IF(OR(G14="",I14=""),"",G14*I14)
J15: =IF(OR(G15="",I15=""),"",G15*I15)
J16: =IF(OR(G16="",I16=""),"",G16*I16)
... J104: =IF(OR(G104="",I104=""),"",G104*I104)

Sheet Cash Flow
A1: DAILY CASH FLOW & RECONCILIATION
A2: Cash sales and cash expenses pull automatically. Enter other cash movements and actual closing cash.
A4: Date | B4: Opening Cash (₱) | C4: Cash Sales (₱) | D4: Other Cash In (₱) | E4: Cash Expenses (₱) | F4: Other Cash Out (₱) | G4: Total Cash In (₱) | H4: Total Cash Out (₱) | I4: Expected Closing (₱) | J4: Actual Closing (₱) | K4: Cash Variance (₱) | L4: Notes
A5: =Lists!$B$5 -> 46204 | B5: =0 -> 0 | C5: =SUMIFS(Orders!$M$5:$M$154,Orders!$B$5:$B$154,A5,Orders!$P$5:$P$154,"Cash",Orders!$Q$5:$Q$154,"Paid",Orders!$R$5:$R$154,"Completed") -> 0 | E5: =SUMIFS(Expenses!$J$5:$J$104,Expenses!$B$5:$B$104,A5,Expenses!$K$5:$K$104,"Cash",Expenses!$M$5:$M$104,"Paid") -> 0 | G5: =C5+IF(D5="",0,D5) -> 0 | H5: =E5+IF(F5="",0,F5) -> 0 | I5: =B5+G5-H5 -> 0 | K5: =IF(J5="","",J5-I5)
A6: =A5+1 -> 46205 | B6: =IF(J5<>"",J5,I5) -> 0 | C6: =SUMIFS(Orders!$M$5:$M$154,Orders!$B$5:$B$154,A6,Orders!$P$5:$P$154,"Cash",Orders!$Q$5:$Q$154,"Paid",Orders!$R$5:$R$154,"Completed") -> 0 | E6: =SUMIFS(Expenses!$J$5:$J$104,Expenses!$B$5:$B$104,A6,Expenses!$K$5:$K$104,"Cash",Expenses!$M$5:$M$104,"Paid") -> 0 | G6: =C6+IF(D6="",0,D6) -> 0 | H6: =E6+IF(F6="",0,F6) -> 0 | I6: =B6+G6-H6 -> 0 | K6: =IF(J6="","",J6-I6)
A7: =A6+1 -> 46206 | B7: =IF(J6<>"",J6,I6) -> 0 | C7: =SUMIFS(Orders!$M$5:$M$154,Orders!$B$5:$B$154,A7,Orders!$P$5:$P$154,"Cash",Orders!$Q$5:$Q$154,"Paid",Orders!$R$5:$R$154,"Completed") -> 0 | E7: =SUMIFS(Expenses!$J$5:$J$104,Expenses!$B$5:$B$104,A7,Expenses!$K$5:$K$104,"Cash",Expenses!$M$5:$M$104,"Paid") -> 0 | G7: =C7+IF(D7="",0,D7) -> 0 | H7: =E7+IF(F7="",0,F7) -> 0 | I7: =B7+G7-H7 -> 0 | K7: =IF(J7="","",J7-I7)
A8: =A7+1 -> 46207 | B8: =IF(J7<>"",J7,I7) -> 0 | C8: =SUMIFS(Orders!$M$5:$M$154,Orders!$B$5:$B$154,A8,Orders!$P$5:$P$154,"Cash",Orders!$Q$5:$Q$154,"Paid",Orders!$R$5:$R$154,"Completed") -> 0 | E8: =SUMIFS(Expenses!$J$5:$J$104,Expenses!$B$5:$B$104,A8,Expenses!$K$5:$K$104,"Cash",Expenses!$M$5:$M$104,"Paid") -> 0 | G8: =C8+IF(D8="",0,D8) -> 0 | H8: =E8+IF(F8="",0,F8) -> 0 | I8: =B8+G8-H8 -> 0 | K8: =IF(J8="","",J8-I8)
A9: =A8+1 -> 46208 | B9: =IF(J8<>"",J8,I8) -> 0 | C9: =SUMIFS(Orders!$M$5:$M$154,Orders!$B$5:$B$154,A9,Orders!$P$5:$P$154,"Cash",Orders!$Q$5:$Q$154,"Paid",Orders!$R$5:$R$154,"Completed") -> 0 | E9: =SUMIFS(Expenses!$J$5:$J$104,Expenses!$B$5:$B$104,A9,Expenses!$K$5:$K$104,"Cash",Expenses!$M$5:$M$104,"Paid") -> 0 | G9: =C9+IF(D9="",0,D9) -> 0 | H9: =E9+IF(F9="",0,F9) -> 0 | I9: =B9+G9-H9 -> 0 | K9: =IF(J9="","",J9-I9)
A10: =A9+1 -> 46209 | B10: =IF(J9<>"",J9,I9) -> 0 | C10: =SUMIFS(Orders!$M$5:$M$154,Orders!$B$5:$B$154,A10,Orders!$P$5:$P$154,"Cash",Orders!$Q$5:$Q$154,"Paid",Orders!$R$5:$R$154,"Completed") -> 0 | E10: =SUMIFS(Expenses!$J$5:$J$104,Expenses!$B$5:$B$104,A10,Expenses!$K$5:$K$104,"Cash",Expenses!$M$5:$M$104,"Paid") -> 0 | G10: =C10+IF(D10="",0,D10) -> 0 | H10: =E10+IF(F10="",0,F10) -> 0 | I10: =B10+G10-H10 -> 0 | K10: =IF(J10="","",J10-I10)
A11: =A10+1 -> 46210 | B11: =IF(J10<>"",J10,I10) -> 0 | C11: =SUMIFS(Orders!$M$5:$M$154,Orders!$B$5:$B$154,A11,Orders!$P$5:$P$154,"Cash",Orders!$Q$5:$Q$154,"Paid",Orders!$R$5:$R$154,"Completed") -> 0 | E11: =SUMIFS(Expenses!$J$5:$J$104,Expenses!$B$5:$B$104,A11,Expenses!$K$5:$K$104,"Cash",Expenses!$M$5:$M$104,"Paid") -> 0 | G11: =C11+IF(D11="",0,D11) -> 0 | H11: =E11+IF(F11="",0,F11) -> 0 | I11: =B11+G11-H11 -> 0 | K11: =IF(J11="","",J11-I11)
A12: =A11+1 -> 46211 | B12: =IF(J11<>"",J11,I11) -> 0 | C12: =SUMIFS(Orders!$M$5:$M$154,Orders!$B$5:$B$154,A12,Orders!$P$5:$P$154,"Cash",Orders!$Q$5:$Q$154,"Paid",Orders!$R$5:$R$154,"Completed") -> 0 | E12: =SUMIFS(Expenses!$J$5:$J$104,Expenses!$B$5:$B$104,A12,Expenses!$K$5:$K$104,"Cash",Expenses!$M$5:$M$104,"Paid") -> 0 | G12: =C12+IF(D12="",0,D12) -> 0 | H12: =E12+IF(F12="",0,F12) -> 0 | I12: =B12+G12-H12 -> 0 | K12: =IF(J12="","",J12-I12)
A13: =A12+1 -> 46212 | B13: =IF(J12<>"",J12,I12) -> 0 | C13: =SUMIFS(Orders!$M$5:$M$154,Orders!$B$5:$B$154,A13,Orders!$P$5:$P$154,"Cash",Orders!$Q$5:$Q$154,"Paid",Orders!$R$5:$R$154,"Completed") -> 0 | E13: =SUMIFS(Expenses!$J$5:$J$104,Expenses!$B$5:$B$104,A13,Expenses!$K$5:$K$104,"Cash",Expenses!$M$5:$M$104,"Paid") -> 0 | G13: =C13+IF(D13="",0,D13) -> 0 | H13: =E13+IF(F13="",0,F13) -> 0 | I13: =B13+G13-H13 -> 0 | K13: =IF(J13="","",J13-I13)
A14: =A13+1 -> 46213 | B14: =IF(J13<>"",J13,I13) -> 0 | C14: =SUMIFS(Orders!$M$5:$M$154,Orders!$B$5:$B$154,A14,Orders!$P$5:$P$154,"Cash",Orders!$Q$5:$Q$154,"Paid",Orders!$R$5:$R$154,"Completed") -> 0 | E14: =SUMIFS(Expenses!$J$5:$J$104,Expenses!$B$5:$B$104,A14,Expenses!$K$5:$K$104,"Cash",Expenses!$M$5:$M$104,"Paid") -> 0 | G14: =C14+IF(D14="",0,D14) -> 0 | H14: =E14+IF(F14="",0,F14) -> 0 | I14: =B14+G14-H14 -> 0 | K14: =IF(J14="","",J14-I14)
A15: =A14+1 -> 46214 | B15: =IF(J14<>"",J14,I14) -> 0 | C15: =SUMIFS(Orders!$M$5:$M$154,Orders!$B$5:$B$154,A15,Orders!$P$5:$P$154,"Cash",Orders!$Q$5:$Q$154,"Paid",Orders!$R$5:$R$154,"Completed") -> 0 | E15: =SUMIFS(Expenses!$J$5:$J$104,Expenses!$B$5:$B$104,A15,Expenses!$K$5:$K$104,"Cash",Expenses!$M$5:$M$104,"Paid") -> 0 | G15: =C15+IF(D15="",0,D15) -> 0 | H15: =E15+IF(F15="",0,F15) -> 0 | I15: =B15+G15-H15 -> 0 | K15: =IF(J15="","",J15-I15)
A16: =A15+1 -> 46215 | B16: =IF(J15<>"",J15,I15) -> 0 | C16: =SUMIFS(Orders!$M$5:$M$154,Orders!$B$5:$B$154,A16,Orders!$P$5:$P$154,"Cash",Orders!$Q$5:$Q$154,"Paid",Orders!$R$5:$R$154,"Completed") -> 0 | E16: =SUMIFS(Expenses!$J$5:$J$104,Expenses!$B$5:$B$104,A16,Expenses!$K$5:$K$104,"Cash",Expenses!$M$5:$M$104,"Paid") -> 0 | G16: =C16+IF(D16="",0,D16) -> 0 | H16: =E16+IF(F16="",0,F16) -> 0 | I16: =B16+G16-H16 -> 0 | K16: =IF(J16="","",J16-I16)
A17: =A16+1 -> 46216 | B17: =IF(J16<>"",J16,I16) -> 0 | C17: =SUMIFS(Orders!$M$5:$M$154,Orders!$B$5:$B$154,A17,Orders!$P$5:$P$154,"Cash",Orders!$Q$5:$Q$154,"Paid",Orders!$R$5:$R$154,"Completed") -> 0 | E17: =SUMIFS(Expenses!$J$5:$J$104,Expenses!$B$5:$B$104,A17,Expenses!$K$5:$K$104,"Cash",Expenses!$M$5:$M$104,"Paid") -> 0 | G17: =C17+IF(D17="",0,D17) -> 0 | H17: =E17+IF(F17="",0,F17) -> 0 | I17: =B17+G17-H17 -> 0 | K17: =IF(J17="","",J17-I17)
... A204: =A203+1 -> 46403 | B204: =IF(J203<>"",J203,I203) -> 0 | C204: =SUMIFS(Orders!$M$5:$M$154,Orders!$B$5:$B$154,A204,Orders!$P$5:$P$154,"Cash",Orders!$Q$5:$Q$154,"Paid",Orders!$R$5:$R$154,"Completed") -> 0 | E204: =SUMIFS(Expenses!$J$5:$J$104,Expenses!$B$5:$B$104,A204,Expenses!$K$5:$K$104,"Cash",Expenses!$M$5:$M$104,"Paid") -> 0 | G204: =C204+IF(D204="",0,D204) -> 0 | H204: =E204+IF(F204="",0,F204) -> 0 | I204: =B204+G204-H204 -> 0 | K204: =IF(J204="","",J204-I204)

Sheet Menu & Pricing
A1: MENU & PRICING
A2: Replace the sample menu. Each size or variation should have a unique Menu Item / Variant name.
A4: Menu Item / Variant | B4: Category | C4: Product Name | D4: Size | E4: Selling Price (₱) | F4: Est. Unit Cost (₱) | G4: Profit per Item (₱) | H4: Profit Margin | I4: Status | J4: Notes
A5: Americano - Regular | B5: Coffee | C5: Americano | D5: Regular | E5: 90 | F5: 25 | G5: =IF(OR(E5="",F5=""),"",E5-F5) -> 65 | H5: =IFERROR(G5/E5,0) -> 0.72222222 | I5: Available | J5: Edit or replace
A6: Cafe Latte - Regular | B6: Coffee | C6: Cafe Latte | D6: Regular | E6: 120 | F6: 45 | G6: =IF(OR(E6="",F6=""),"",E6-F6) -> 75 | H6: =IFERROR(G6/E6,0) -> 0.625 | I6: Available | J6: Edit or replace
A7: Spanish Latte - Regular | B7: Coffee | C7: Spanish Latte | D7: Regular | E7: 130 | F7: 50 | G7: =IF(OR(E7="",F7=""),"",E7-F7) -> 80 | H7: =IFERROR(G7/E7,0) -> 0.61538462 | I7: Available | J7: Edit or replace
A8: Caramel Macchiato - Regular | B8: Coffee | C8: Caramel Macchiato | D8: Regular | E8: 140 | F8: 55 | G8: =IF(OR(E8="",F8=""),"",E8-F8) -> 85 | H8: =IFERROR(G8/E8,0) -> 0.60714286 | I8: Available | J8: Edit or replace
A9: Matcha Latte - Regular | B9: Tea & Matcha | C9: Matcha Latte | D9: Regular | E9: 140 | F9: 60 | G9: =IF(OR(E9="",F9=""),"",E9-F9) -> 80 | H9: =IFERROR(G9/E9,0) -> 0.57142857 | I9: Available | J9: Edit or replace
A10: Chocolate Drink - Regular | B10: Non-Coffee | C10: Chocolate Drink | D10: Regular | E10: 120 | F10: 45 | G10: =IF(OR(E10="",F10=""),"",E10-F10) -> 75 | H10: =IFERROR(G10/E10,0) -> 0.625 | I10: Available | J10: Edit or replace
A11: Croissant | B11: Food | C11: Croissant | D11: Regular | E11: 95 | F11: 50 | G11: =IF(OR(E11="",F11=""),"",E11-F11) -> 45 | H11: =IFERROR(G11/E11,0) -> 0.47368421 | I11: Available | J11: Edit or replace
A12: Extra Espresso Shot | B12: Add-on | C12: Extra Espresso Shot | D12: Regular | E12: 30 | F12: 12 | G12: =IF(OR(E12="",F12=""),"",E12-F12) -> 18 | H12: =IFERROR(G12/E12,0) -> 0.6 | I12: Available | J12: Edit or replace
G13: =IF(OR(E13="",F13=""),"",E13-F13) | H13: =IFERROR(G13/E13,0) -> 0
G14: =IF(OR(E14="",F14=""),"",E14-F14) | H14: =IFERROR(G14/E14,0) -> 0
G15: =IF(OR(E15="",F15=""),"",E15-F15) | H15: =IFERROR(G15/E15,0) -> 0
G16: =IF(OR(E16="",F16=""),"",E16-F16) | H16: =IFERROR(G16/E16,0) -> 0
G17: =IF(OR(E17="",F17=""),"",E17-F17) | H17: =IFERROR(G17/E17,0) -> 0
G18: =IF(OR(E18="",F18=""),"",E18-F18) | H18: =IFERROR(G18/E18,0) -> 0
G19: =IF(OR(E19="",F19=""),"",E19-F19) | H19: =IFERROR(G19/E19,0) -> 0
G20: =IF(OR(E20="",F20=""),"",E20-F20) | H20: =IFERROR(G20/E20,0) -> 0
G21: =IF(OR(E21="",F21=""),"",E21-F21) | H21: =IFERROR(G21/E21,0) -> 0
G22: =IF(OR(E22="",F22=""),"",E22-F22) | H22: =IFERROR(G22/E22,0) -> 0
G23: =IF(OR(E23="",F23=""),"",E23-F23) | H23: =IFERROR(G23/E23,0) -> 0
G24: =IF(OR(E24="",F24=""),"",E24-F24) | H24: =IFERROR(G24/E24,0) -> 0
... G54: =IF(OR(E54="",F54=""),"",E54-F54) | H54: =IFERROR(G54/E54,0) -> 0

Sheet Inventory
A1: INVENTORY TRACKER
A2: Update stock in, stock used, and wastage. Ending stock and reorder status calculate automatically.
A4: Item ID | B4: Ingredient / Supply | C4: Category | D4: Unit | E4: Beginning Stock | F4: Stock In | G4: Stock Used | H4: Wastage | I4: Ending Stock | J4: Reorder Level | K4: Stock Status | L4: Unit Cost (₱) | M4: Inventory Value (₱) | N4: Supplier | O4: Expiration Date | P4: Last Updated
A5: INV-001 | B5: Coffee Beans | C5: Ingredient | D5: gram | E5: 1000 | F5: 0 | G5: 0 | H5: 0 | I5: =IF(A5="","",E5+F5-G5-H5) -> 1000 | J5: 300 | K5: =IF(I5="","",IF(I5<=J5,"REORDER","OK")) -> OK | L5: 1.2 | M5: =IF(OR(I5="",L5=""),"",I5*L5) -> 1200 | P5: 46216
A6: INV-002 | B6: Fresh Milk | C6: Ingredient | D6: milliliter | E6: 5000 | F6: 0 | G6: 0 | H6: 0 | I6: =IF(A6="","",E6+F6-G6-H6) -> 5000 | J6: 1000 | K6: =IF(I6="","",IF(I6<=J6,"REORDER","OK")) -> OK | L6: 0.1 | M6: =IF(OR(I6="",L6=""),"",I6*L6) -> 500 | P6: 46216
A7: INV-003 | B7: 12 oz Cups | C7: Packaging | D7: piece | E7: 100 | F7: 0 | G7: 0 | H7: 0 | I7: =IF(A7="","",E7+F7-G7-H7) -> 100 | J7: 30 | K7: =IF(I7="","",IF(I7<=J7,"REORDER","OK")) -> OK | L7: 5 | M7: =IF(OR(I7="",L7=""),"",I7*L7) -> 500 | P7: 46216
A8: INV-004 | B8: Cup Lids | C8: Packaging | D8: piece | E8: 100 | F8: 0 | G8: 0 | H8: 0 | I8: =IF(A8="","",E8+F8-G8-H8) -> 100 | J8: 30 | K8: =IF(I8="","",IF(I8<=J8,"REORDER","OK")) -> OK | L8: 3 | M8: =IF(OR(I8="",L8=""),"",I8*L8) -> 300 | P8: 46216
I9: =IF(A9="","",E9+F9-G9-H9) | K9: =IF(I9="","",IF(I9<=J9,"REORDER","OK")) | M9: =IF(OR(I9="",L9=""),"",I9*L9)
I10: =IF(A10="","",E10+F10-G10-H10) | K10: =IF(I10="","",IF(I10<=J10,"REORDER","OK")) | M10: =IF(OR(I10="",L10=""),"",I10*L10)
I11: =IF(A11="","",E11+F11-G11-H11) | K11: =IF(I11="","",IF(I11<=J11,"REORDER","OK")) | M11: =IF(OR(I11="",L11=""),"",I11*L11)
I12: =IF(A12="","",E12+F12-G12-H12) | K12: =IF(I12="","",IF(I12<=J12,"REORDER","OK")) | M12: =IF(OR(I12="",L12=""),"",I12*L12)
I13: =IF(A13="","",E13+F13-G13-H13) | K13: =IF(I13="","",IF(I13<=J13,"REORDER","OK")) | M13: =IF(OR(I13="",L13=""),"",I13*L13)
I14: =IF(A14="","",E14+F14-G14-H14) | K14: =IF(I14="","",IF(I14<=J14,"REORDER","OK")) | M14: =IF(OR(I14="",L14=""),"",I14*L14)
I15: =IF(A15="","",E15+F15-G15-H15) | K15: =IF(I15="","",IF(I15<=J15,"REORDER","OK")) | M15: =IF(OR(I15="",L15=""),"",I15*L15)
I16: =IF(A16="","",E16+F16-G16-H16) | K16: =IF(I16="","",IF(I16<=J16,"REORDER","OK")) | M16: =IF(OR(I16="",L16=""),"",I16*L16)
I17: =IF(A17="","",E17+F17-G17-H17) | K17: =IF(I17="","",IF(I17<=J17,"REORDER","OK")) | M17: =IF(OR(I17="",L17=""),"",I17*L17)
I18: =IF(A18="","",E18+F18-G18-H18) | K18: =IF(I18="","",IF(I18<=J18,"REORDER","OK")) | M18: =IF(OR(I18="",L18=""),"",I18*L18)
I19: =IF(A19="","",E19+F19-G19-H19) | K19: =IF(I19="","",IF(I19<=J19,"REORDER","OK")) | M19: =IF(OR(I19="",L19=""),"",I19*L19)
I20: =IF(A20="","",E20+F20-G20-H20) | K20: =IF(I20="","",IF(I20<=J20,"REORDER","OK")) | M20: =IF(OR(I20="",L20=""),"",I20*L20)
... I104: =IF(A104="","",E104+F104-G104-H104) | K104: =IF(I104="","",IF(I104<=J104,"REORDER","OK")) | M104: =IF(OR(I104="",L104=""),"",I104*L104)

Sheet Daily Summary
A1: DAILY SALES & PROFIT SUMMARY
A2: Automatic daily totals beginning from the Tracker Start Date in Lists.
A4: Date | B4: Gross Sales (₱) | C4: Discounts (₱) | D4: Net Sales (₱) | E4: Est. COGS (₱) | F4: Operating Expenses (₱) | G4: Gross Profit (₱) | H4: Net Profit (₱) | I4: Total Orders | J4: Items Sold | K4: Cash Sales (₱) | L4: Digital Sales (₱) | M4: Paid Cash Out (₱)
A5: =Lists!$B$5 -> 46204 | B5: =SUMIFS(Orders!$K$5:$K$154,Orders!$B$5:$B$154,$A5,Orders!$Q$5:$Q$154,"Paid",Orders!$R$5:$R$154,"Completed") -> 0 | C5: =SUMIFS(Orders!$L$5:$L$154,Orders!$B$5:$B$154,$A5,Orders!$Q$5:$Q$154,"Paid",Orders!$R$5:$R$154,"Completed") -> 0 | D5: =SUMIFS(Orders!$M$5:$M$154,Orders!$B$5:$B$154,$A5,Orders!$Q$5:$Q$154,"Paid",Orders!$R$5:$R$154,"Completed") -> 0 | E5: =SUMIFS(Orders!$O$5:$O$154,Orders!$B$5:$B$154,$A5,Orders!$Q$5:$Q$154,"Paid",Orders!$R$5:$R$154,"Completed") -> 0 | F5: =SUMIFS(Expenses!$J$5:$J$104,Expenses!$B$5:$B$104,$A5,Expenses!$L$5:$L$104,"Operating Expense",Expenses!$M$5:$M$104,"Paid") -> 0 | G5: =D5-E5 -> 0 | H5: =G5-F5 -> 0 | I5: =SUMIFS(Orders!$U$5:$U$154,Orders!$B$5:$B$154,$A5) -> 0 | J5: =SUMIFS(Orders!$H$5:$H$154,Orders!$B$5:$B$154,$A5,Orders!$Q$5:$Q$154,"Paid",Orders!$R$5:$R$154,"Completed") -> 0 | K5: =SUMIFS(Orders!$M$5:$M$154,Orders!$B$5:$B$154,$A5,Orders!$P$5:$P$154,"Cash",Orders!$Q$5:$Q$154,"Paid",Orders!$R$5:$R$154,"Completed") -> 0 | L5: =D5-K5 -> 0 | M5: =SUMIFS(Expenses!$J$5:$J$104,Expenses!$B$5:$B$104,$A5,Expenses!$M$5:$M$104,"Paid") -> 0
A6: =A5+1 -> 46205 | B6: =SUMIFS(Orders!$K$5:$K$154,Orders!$B$5:$B$154,$A6,Orders!$Q$5:$Q$154,"Paid",Orders!$R$5:$R$154,"Completed") -> 0 | C6: =SUMIFS(Orders!$L$5:$L$154,Orders!$B$5:$B$154,$A6,Orders!$Q$5:$Q$154,"Paid",Orders!$R$5:$R$154,"Completed") -> 0 | D6: =SUMIFS(Orders!$M$5:$M$154,Orders!$B$5:$B$154,$A6,Orders!$Q$5:$Q$154,"Paid",Orders!$R$5:$R$154,"Completed") -> 0 | E6: =SUMIFS(Orders!$O$5:$O$154,Orders!$B$5:$B$154,$A6,Orders!$Q$5:$Q$154,"Paid",Orders!$R$5:$R$154,"Completed") -> 0 | F6: =SUMIFS(Expenses!$J$5:$J$104,Expenses!$B$5:$B$104,$A6,Expenses!$L$5:$L$104,"Operating Expense",Expenses!$M$5:$M$104,"Paid") -> 0 | G6: =D6-E6 -> 0 | H6: =G6-F6 -> 0 | I6: =SUMIFS(Orders!$U$5:$U$154,Orders!$B$5:$B$154,$A6) -> 0 | J6: =SUMIFS(Orders!$H$5:$H$154,Orders!$B$5:$B$154,$A6,Orders!$Q$5:$Q$154,"Paid",Orders!$R$5:$R$154,"Completed") -> 0 | K6: =SUMIFS(Orders!$M$5:$M$154,Orders!$B$5:$B$154,$A6,Orders!$P$5:$P$154,"Cash",Orders!$Q$5:$Q$154,"Paid",Orders!$R$5:$R$154,"Completed") -> 0 | L6: =D6-K6 -> 0 | M6: =SUMIFS(Expenses!$J$5:$J$104,Expenses!$B$5:$B$104,$A6,Expenses!$M$5:$M$104,"Paid") -> 0
A7: =A6+1 -> 46206 | B7: =SUMIFS(Orders!$K$5:$K$154,Orders!$B$5:$B$154,$A7,Orders!$Q$5:$Q$154,"Paid",Orders!$R$5:$R$154,"Completed") -> 0 | C7: =SUMIFS(Orders!$L$5:$L$154,Orders!$B$5:$B$154,$A7,Orders!$Q$5:$Q$154,"Paid",Orders!$R$5:$R$154,"Completed") -> 0 | D7: =SUMIFS(Orders!$M$5:$M$154,Orders!$B$5:$B$154,$A7,Orders!$Q$5:$Q$154,"Paid",Orders!$R$5:$R$154,"Completed") -> 0 | E7: =SUMIFS(Orders!$O$5:$O$154,Orders!$B$5:$B$154,$A7,Orders!$Q$5:$Q$154,"Paid",Orders!$R$5:$R$154,"Completed") -> 0 | F7: =SUMIFS(Expenses!$J$5:$J$104,Expenses!$B$5:$B$104,$A7,Expenses!$L$5:$L$104,"Operating Expense",Expenses!$M$5:$M$104,"Paid") -> 0 | G7: =D7-E7 -> 0 | H7: =G7-F7 -> 0 | I7: =SUMIFS(Orders!$U$5:$U$154,Orders!$B$5:$B$154,$A7) -> 0 | J7: =SUMIFS(Orders!$H$5:$H$154,Orders!$B$5:$B$154,$A7,Orders!$Q$5:$Q$154,"Paid",Orders!$R$5:$R$154,"Completed") -> 0 | K7: =SUMIFS(Orders!$M$5:$M$154,Orders!$B$5:$B$154,$A7,Orders!$P$5:$P$154,"Cash",Orders!$Q$5:$Q$154,"Paid",Orders!$R$5:$R$154,"Completed") -> 0 | L7: =D7-K7 -> 0 | M7: =SUMIFS(Expenses!$J$5:$J$104,Expenses!$B$5:$B$104,$A7,Expenses!$M$5:$M$104,"Paid") -> 0
